<?xml version="1.0" encoding="UTF-8" ?>
<rss version="2.0" xmlns:atom="http://www.w3.org/2005/Atom" xmlns:dc="http://purl.org/dc/elements/1.1/">
  <channel>
    <title>שאלה מקצועית - exceptions</title>
    <link>https://forums.pythonic.guru/t/exceptions/8476</link>
    <description>היי, אשמח לעזרה.

השאלה היא כללית- כמובן שלרוב לא אבצע את זה כך(שילוב של rasie וtry-except), אבל אני מנסה להבין איך פייתון עובדת.
בתוכנית השתמשתי בבלוק של try-except-finally
בתוך בלוק הtry השתמשתי בתנאי שבמידה ומקיים-  rasie שגיאה מסויימת(נניח ValueError)
הבלוק של הexcept לא תופס את השגיאה הזו.
כשאני מריץ את התוכנה, השגיאה קופצת אבל התוכנית ממשיכה לבלוק של הfinally =למרות שהקוד כולו אמור לקרוס.(שאני עובר על הדיבוג הוא קופץ משורת הraise לexcept (בלי להיכנס לבלוק except) ואז ממשיך לfinally - בלי לקרוס.

אשמח להבין איך עובד התהליך :slight_smile:
(חיפשתי באינטרנט כמובן ועברתי על המחברות אבל לא מצאתי תשובה שמכילה את המקרה )</description>
    <language>he</language>
    <lastBuildDate>Wed, 25 Nov 2020 12:30:11 +0000</lastBuildDate>
    <category>מחוץ לקטגוריה</category>
    <atom:link href="https://forums.pythonic.guru/t/exceptions/8476.rss" rel="self" type="application/rss+xml" />
      <item>
        <title>שאלה מקצועית - exceptions</title>
        <dc:creator><![CDATA[Yam]]></dc:creator>
        <description><![CDATA[
            <p>ה־<code>except</code> לא תופס <code>ValueError</code> אלא <code>IOError</code></p>
          <p><a href="https://forums.pythonic.guru/t/exceptions/8476/4">קריאת הנושא במלואו</a></p>
        ]]></description>
        <link>https://forums.pythonic.guru/t/exceptions/8476/4</link>
        <pubDate>Wed, 25 Nov 2020 12:30:11 +0000</pubDate>
        <guid isPermaLink="false">forums.pythonic.guru-post-8476-4</guid>
        <source url="https://forums.pythonic.guru/t/exceptions/8476.rss">שאלה מקצועית - exceptions</source>
      </item>
      <item>
        <title>שאלה מקצועית - exceptions</title>
        <dc:creator><![CDATA[ofirhaimofir96]]></dc:creator>
        <description><![CDATA[
            <p>כן מצורף,(לא קוד שאני כתבתי או משהו), פשוט אני מנסה להבין למה הוא לא מקפיץ את השגיאה ומקריס את התוכנית?<br>
</p><div class="lightbox-wrapper"><a class="lightbox" href="https://forums.pythonic.guru/uploads/default/original/2X/1/1f8781e86aa52b205db7fed6ba30e7ebfa469b89.png" data-download-href="https://forums.pythonic.guru/uploads/default/1f8781e86aa52b205db7fed6ba30e7ebfa469b89" title="image"><img src="https://forums.pythonic.guru/uploads/default/optimized/2X/1/1f8781e86aa52b205db7fed6ba30e7ebfa469b89_2_659x500.png" alt="image" data-base62-sha1="4uV7Km0idRhwjTX8GxyBHdOA0J3" width="659" height="500" srcset="https://forums.pythonic.guru/uploads/default/optimized/2X/1/1f8781e86aa52b205db7fed6ba30e7ebfa469b89_2_659x500.png, https://forums.pythonic.guru/uploads/default/original/2X/1/1f8781e86aa52b205db7fed6ba30e7ebfa469b89.png 1.5x, https://forums.pythonic.guru/uploads/default/original/2X/1/1f8781e86aa52b205db7fed6ba30e7ebfa469b89.png 2x" data-small-upload="https://forums.pythonic.guru/uploads/default/optimized/2X/1/1f8781e86aa52b205db7fed6ba30e7ebfa469b89_2_10x10.png"></a></div><p></p>
<p>תודה ים.</p>
          <p><a href="https://forums.pythonic.guru/t/exceptions/8476/3">קריאת הנושא במלואו</a></p>
        ]]></description>
        <link>https://forums.pythonic.guru/t/exceptions/8476/3</link>
        <pubDate>Wed, 25 Nov 2020 11:47:23 +0000</pubDate>
        <guid isPermaLink="false">forums.pythonic.guru-post-8476-3</guid>
        <source url="https://forums.pythonic.guru/t/exceptions/8476.rss">שאלה מקצועית - exceptions</source>
      </item>
      <item>
        <title>שאלה מקצועית - exceptions</title>
        <dc:creator><![CDATA[Yam]]></dc:creator>
        <description><![CDATA[
            <p>אפשר לראות בבקשה את הקוד? <img src="https://forums.pythonic.guru/images/emoji/twitter/slight_smile.png?v=9" title=":slight_smile:" class="emoji" alt=":slight_smile:"></p>
          <p><a href="https://forums.pythonic.guru/t/exceptions/8476/2">קריאת הנושא במלואו</a></p>
        ]]></description>
        <link>https://forums.pythonic.guru/t/exceptions/8476/2</link>
        <pubDate>Wed, 25 Nov 2020 10:58:18 +0000</pubDate>
        <guid isPermaLink="false">forums.pythonic.guru-post-8476-2</guid>
        <source url="https://forums.pythonic.guru/t/exceptions/8476.rss">שאלה מקצועית - exceptions</source>
      </item>
      <item>
        <title>שאלה מקצועית - exceptions</title>
        <dc:creator><![CDATA[ofirhaimofir96]]></dc:creator>
        <description><![CDATA[
            <p>היי, אשמח לעזרה.</p>
<p>השאלה היא כללית- כמובן שלרוב לא אבצע את זה כך(שילוב של rasie וtry-except), אבל אני מנסה להבין איך פייתון עובדת.<br>
בתוכנית השתמשתי בבלוק של try-except-finally<br>
בתוך בלוק הtry השתמשתי בתנאי שבמידה ומקיים-  rasie שגיאה מסויימת(נניח ValueError)<br>
הבלוק של הexcept לא תופס את השגיאה הזו.<br>
כשאני מריץ את התוכנה, השגיאה קופצת אבל התוכנית ממשיכה לבלוק של הfinally =למרות שהקוד כולו אמור לקרוס.(שאני עובר על הדיבוג הוא קופץ משורת הraise לexcept (בלי להיכנס לבלוק except) ואז ממשיך לfinally - בלי לקרוס.</p>
<p>אשמח להבין איך עובד התהליך <img src="https://forums.pythonic.guru/images/emoji/twitter/slight_smile.png?v=9" title=":slight_smile:" class="emoji" alt=":slight_smile:"><br>
(חיפשתי באינטרנט כמובן ועברתי על המחברות אבל לא מצאתי תשובה שמכילה את המקרה )</p>
          <p><a href="https://forums.pythonic.guru/t/exceptions/8476/1">קריאת הנושא במלואו</a></p>
        ]]></description>
        <link>https://forums.pythonic.guru/t/exceptions/8476/1</link>
        <pubDate>Wed, 25 Nov 2020 09:01:59 +0000</pubDate>
        <guid isPermaLink="false">forums.pythonic.guru-post-8476-1</guid>
        <source url="https://forums.pythonic.guru/t/exceptions/8476.rss">שאלה מקצועית - exceptions</source>
      </item>
  </channel>
</rss>
