<?xml version="1.0" encoding="UTF-8" ?>
<rss version="2.0" xmlns:atom="http://www.w3.org/2005/Atom" xmlns:dc="http://purl.org/dc/elements/1.1/">
  <channel>
    <title>פותחים שעון - בהרצה מתעלמים מאחד ה-Except</title>
    <link>https://forums.pythonic.guru/t/except/7668</link>
    <description>כשאני מנסה להריץ בקוד בכוונה path של קובץ &quot;בעייתי&quot; שאינו טקסט,
נראה כאילו יש התעלמות מהexcept שהכנסתי עבור המצב הזה. 
כשאני מכניסה בכוונה Path &quot;בעייתי&quot;, בהודעת השגיאה נכתב שבזמן שטיפלו בUnicodeDecodeError, נתקלו בexception אחר -UnboundLocalErrord -בנוגע למשתנה שהתייחסתי אליו לפני שהתבצעה השמה. אבל כן מתבצעת השמה למשתנה, בתוך הexception של הUnicodeDecodeError, אבל משום מה נראה כאילו מה שבתוך הexcept לא מתבצע. ה-except השני דווקא כן עובד.
מצרפת כאן קישור למערכת בדיקה כדי שיהיה אפשר לראות את הקוד - https://solve.pythonic.guru/view/109144</description>
    <language>he</language>
    <lastBuildDate>Mon, 27 Jul 2020 21:24:51 +0000</lastBuildDate>
    <category>שבוע 8</category>
    <atom:link href="https://forums.pythonic.guru/t/except/7668.rss" rel="self" type="application/rss+xml" />
      <item>
        <title>פותחים שעון - בהרצה מתעלמים מאחד ה-Except</title>
        <dc:creator><![CDATA[car.chopin]]></dc:creator>
        <description><![CDATA[
            <p>אצטרך לחשוב עוד זמן מה על החידה הזאת :rofl<br>
תודה בכל אופן על הסיוע המתמיד!</p>
          <p><a href="https://forums.pythonic.guru/t/except/7668/3">קריאת הנושא במלואו</a></p>
        ]]></description>
        <link>https://forums.pythonic.guru/t/except/7668/3</link>
        <pubDate>Mon, 27 Jul 2020 21:24:51 +0000</pubDate>
        <guid isPermaLink="false">forums.pythonic.guru-post-7668-3</guid>
        <source url="https://forums.pythonic.guru/t/except/7668.rss">פותחים שעון - בהרצה מתעלמים מאחד ה-Except</source>
      </item>
      <item>
        <title>פותחים שעון - בהרצה מתעלמים מאחד ה-Except</title>
        <dc:creator><![CDATA[devorack]]></dc:creator>
        <description><![CDATA[
            <p>לפי מה שאני נתקלתי מהניסיונות שלי, הexcept לא רץ אם הוא בעצמו נתקל בשגיאה (אחרת / נוספת).<br>
ניצלתי את זה לטובתי <img src="https://forums.pythonic.guru/images/emoji/twitter/wink.png?v=9" title=":wink:" class="emoji" alt=":wink:"></p>
          <p><a href="https://forums.pythonic.guru/t/except/7668/2">קריאת הנושא במלואו</a></p>
        ]]></description>
        <link>https://forums.pythonic.guru/t/except/7668/2</link>
        <pubDate>Mon, 27 Jul 2020 20:16:59 +0000</pubDate>
        <guid isPermaLink="false">forums.pythonic.guru-post-7668-2</guid>
        <source url="https://forums.pythonic.guru/t/except/7668.rss">פותחים שעון - בהרצה מתעלמים מאחד ה-Except</source>
      </item>
      <item>
        <title>פותחים שעון - בהרצה מתעלמים מאחד ה-Except</title>
        <dc:creator><![CDATA[car.chopin]]></dc:creator>
        <description><![CDATA[
            <p>כשאני מנסה להריץ בקוד בכוונה path של קובץ “בעייתי” שאינו טקסט,<br>
נראה כאילו יש התעלמות מהexcept שהכנסתי עבור המצב הזה.<br>
כשאני מכניסה בכוונה Path “בעייתי”, בהודעת השגיאה נכתב שבזמן שטיפלו בUnicodeDecodeError, נתקלו בexception אחר -UnboundLocalErrord -בנוגע למשתנה שהתייחסתי אליו לפני שהתבצעה השמה. אבל כן מתבצעת השמה למשתנה, בתוך הexception של הUnicodeDecodeError, אבל משום מה נראה כאילו מה שבתוך הexcept לא מתבצע. ה-except השני דווקא כן עובד.<br>
מצרפת כאן קישור למערכת בדיקה כדי שיהיה אפשר לראות את הקוד - <a href="https://solve.pythonic.guru/view/109144" rel="nofollow noopener">https://solve.pythonic.guru/view/109144</a></p>
          <p><a href="https://forums.pythonic.guru/t/except/7668/1">קריאת הנושא במלואו</a></p>
        ]]></description>
        <link>https://forums.pythonic.guru/t/except/7668/1</link>
        <pubDate>Mon, 27 Jul 2020 18:30:33 +0000</pubDate>
        <guid isPermaLink="false">forums.pythonic.guru-post-7668-1</guid>
        <source url="https://forums.pythonic.guru/t/except/7668.rss">פותחים שעון - בהרצה מתעלמים מאחד ה-Except</source>
      </item>
  </channel>
</rss>
