<?xml version="1.0" encoding="UTF-8" ?>
<rss version="2.0" xmlns:atom="http://www.w3.org/2005/Atom" xmlns:dc="http://purl.org/dc/elements/1.1/">
  <channel>
    <title>בעייה באימפורטים עם fastapi</title>
    <link>https://forums.pythonic.guru/t/fastapi/8772</link>
    <description>![image|690x281](upload://eV1H7NWb99LdDrDPNstWM8iBTwW.png) 
אני נתקל באי יכולת לייבא כלום מתיקיית database. התוכנה מורצת מתוך תיקיית app, בה, במקביל לקובץ ההרצה ישנה את תיקיית database, ובתוכה ישנו קובץ init. למרות זאת, נסיונות לייבא מתוכו כושלים. ניסיתי במספר דרכים שונות, עד כה ללא הצלחה. הבנתי שאחרים גם נתקלו בזה</description>
    <language>he</language>
    <lastBuildDate>Thu, 14 Jan 2021 16:14:42 +0000</lastBuildDate>
    <category>שבוע 16</category>
    <atom:link href="https://forums.pythonic.guru/t/fastapi/8772.rss" rel="self" type="application/rss+xml" />
      <item>
        <title>בעייה באימפורטים עם fastapi</title>
        <dc:creator><![CDATA[koby]]></dc:creator>
        <description><![CDATA[
            <p>הבעיה היתה שלא הגדרתי את הכתובת לדאטהבייס כמשתנה סביבה. הפתרון היה העברתו לקובץ .env, ושימוש ב- python dot-env</p>
          <p><a href="https://forums.pythonic.guru/t/fastapi/8772/7">קריאת הנושא במלואו</a></p>
        ]]></description>
        <link>https://forums.pythonic.guru/t/fastapi/8772/7</link>
        <pubDate>Thu, 14 Jan 2021 16:14:42 +0000</pubDate>
        <guid isPermaLink="false">forums.pythonic.guru-post-8772-7</guid>
        <source url="https://forums.pythonic.guru/t/fastapi/8772.rss">בעייה באימפורטים עם fastapi</source>
      </item>
      <item>
        <title>בעייה באימפורטים עם fastapi</title>
        <dc:creator><![CDATA[Yam]]></dc:creator>
        <description><![CDATA[
            <p>תוכל להסביר בבקשה מה הייתה הטעות כדי שנוכל למנוע בהמשך? (:</p>
          <p><a href="https://forums.pythonic.guru/t/fastapi/8772/6">קריאת הנושא במלואו</a></p>
        ]]></description>
        <link>https://forums.pythonic.guru/t/fastapi/8772/6</link>
        <pubDate>Thu, 14 Jan 2021 14:49:19 +0000</pubDate>
        <guid isPermaLink="false">forums.pythonic.guru-post-8772-6</guid>
        <source url="https://forums.pythonic.guru/t/fastapi/8772.rss">בעייה באימפורטים עם fastapi</source>
      </item>
      <item>
        <title>בעייה באימפורטים עם fastapi</title>
        <dc:creator><![CDATA[koby]]></dc:creator>
        <description><![CDATA[
            <p>תודה רבה, הסתדרתי עם זה. היתה לי טעות בהגדרת משתני הסביבה.<br>
למרות זאת, ה- VSC עדיין מסמן לי שמות התיקיות באימפורטים, כמו בצילום, למרות שהייבוא מהן עובד. זה לא מונע ממני להמשיך, אבל זה קצת מוזר ולא ברור לי.</p>
          <p><a href="https://forums.pythonic.guru/t/fastapi/8772/5">קריאת הנושא במלואו</a></p>
        ]]></description>
        <link>https://forums.pythonic.guru/t/fastapi/8772/5</link>
        <pubDate>Thu, 14 Jan 2021 08:16:09 +0000</pubDate>
        <guid isPermaLink="false">forums.pythonic.guru-post-8772-5</guid>
        <source url="https://forums.pythonic.guru/t/fastapi/8772.rss">בעייה באימפורטים עם fastapi</source>
      </item>
      <item>
        <title>בעייה באימפורטים עם fastapi</title>
        <dc:creator><![CDATA[Yam]]></dc:creator>
        <description><![CDATA[
            <p>מצטער שאני מגיע לזה רק עכשיו.</p>
<aside class="quote no-group" data-username="koby" data-post="2" data-topic="8772">
<div class="title">
<div class="quote-controls"></div>
<img alt="" width="20" height="20" src="https://forums.pythonic.guru/user_avatar/forums.pythonic.guru/koby/40/2234_2.png" class="avatar"> koby:</div>
<blockquote>
<p>הבנתי שהשימוש ב- os.getenv עבור נתיב קובץ הדאטה בייס</p>
</blockquote>
</aside>
<p>תוכל להצביע על איפה השורה הבעייתית בקוד?<br>
האם הגדרת במשתנה הסביבה  את הנתיב הרלוונטי?</p>
          <p><a href="https://forums.pythonic.guru/t/fastapi/8772/4">קריאת הנושא במלואו</a></p>
        ]]></description>
        <link>https://forums.pythonic.guru/t/fastapi/8772/4</link>
        <pubDate>Thu, 14 Jan 2021 03:47:05 +0000</pubDate>
        <guid isPermaLink="false">forums.pythonic.guru-post-8772-4</guid>
        <source url="https://forums.pythonic.guru/t/fastapi/8772.rss">בעייה באימפורטים עם fastapi</source>
      </item>
      <item>
        <title>בעייה באימפורטים עם fastapi</title>
        <dc:creator><![CDATA[efratush]]></dc:creator>
        <description><![CDATA[
            <p>גם אני נתקלתי בבעיה.</p>
<p><img src="https://forums.pythonic.guru/uploads/default/original/2X/a/aac776395f59dc3acd75d72be27282bc87b30c60.png" alt="image" data-base62-sha1="omMvVqxogA87ZqXcxmaq5vi3ByE" width="478" height="52"></p>
<p>הdb נוצר, ולמרות זאת השגיאה קיימת:</p>
<p><img src="https://forums.pythonic.guru/uploads/default/original/2X/b/b574cca4afc78c0f52c6bafec1f3841c905a053a.png" alt="image" data-base62-sha1="pTeF9cUgSWBaMzRxsArmNHiFYaC" width="254" height="270"></p>
<p>יש למישהו מושג למה?</p>
<p>והאם בכלל צריך להתחבר לdb עם metadata = sqlalchemy.MetaData() ?</p>
          <p><a href="https://forums.pythonic.guru/t/fastapi/8772/3">קריאת הנושא במלואו</a></p>
        ]]></description>
        <link>https://forums.pythonic.guru/t/fastapi/8772/3</link>
        <pubDate>Wed, 13 Jan 2021 18:19:29 +0000</pubDate>
        <guid isPermaLink="false">forums.pythonic.guru-post-8772-3</guid>
        <source url="https://forums.pythonic.guru/t/fastapi/8772.rss">בעייה באימפורטים עם fastapi</source>
      </item>
      <item>
        <title>בעייה באימפורטים עם fastapi</title>
        <dc:creator><![CDATA[koby]]></dc:creator>
        <description><![CDATA[
            <p></p><div class="lightbox-wrapper"><a class="lightbox" href="https://forums.pythonic.guru/uploads/default/original/2X/a/a1b216b3ede202f8011df24eddac450b0987a1aa.png" data-download-href="https://forums.pythonic.guru/uploads/default/a1b216b3ede202f8011df24eddac450b0987a1aa" title="image"><img src="https://forums.pythonic.guru/uploads/default/optimized/2X/a/a1b216b3ede202f8011df24eddac450b0987a1aa_2_690x337.png" alt="image" data-base62-sha1="n4qqpun9Q37uOsUVv0Oi8TiFiie" width="690" height="337" srcset="https://forums.pythonic.guru/uploads/default/optimized/2X/a/a1b216b3ede202f8011df24eddac450b0987a1aa_2_690x337.png, https://forums.pythonic.guru/uploads/default/optimized/2X/a/a1b216b3ede202f8011df24eddac450b0987a1aa_2_1035x505.png 1.5x, https://forums.pythonic.guru/uploads/default/optimized/2X/a/a1b216b3ede202f8011df24eddac450b0987a1aa_2_1380x674.png 2x" data-small-upload="https://forums.pythonic.guru/uploads/default/optimized/2X/a/a1b216b3ede202f8011df24eddac450b0987a1aa_2_10x10.png"></a></div><p></p>
<p>אז לאחר מספר ניסיונות, הבנתי שהשימוש ב- os.getenv עבור נתיב קובץ הדאטה בייס, זה מה שהקפיץ את ההודעה בצילום הקודם, מכיוון שהוא מחזיר None. אז לאחר הסרתו, ושימוש רק בסטרינג, נוצר לי דאטה בייס. מה שמוזר, שעדיין שמות התיקיות בייבואים מסומן, למרות שאם הייבוא לא היה עובד, לא היה נוצר דאטה בייס.<br>
בנוסף, גם לאחר שנוצר קובץ הדאטה בייס, במידה ואני מחזיר את os.getenv, שוב מתקבלת אותה שגיאה, אפילו שהקובץ כבר נמצא</p>
          <p><a href="https://forums.pythonic.guru/t/fastapi/8772/2">קריאת הנושא במלואו</a></p>
        ]]></description>
        <link>https://forums.pythonic.guru/t/fastapi/8772/2</link>
        <pubDate>Wed, 13 Jan 2021 14:55:52 +0000</pubDate>
        <guid isPermaLink="false">forums.pythonic.guru-post-8772-2</guid>
        <source url="https://forums.pythonic.guru/t/fastapi/8772.rss">בעייה באימפורטים עם fastapi</source>
      </item>
      <item>
        <title>בעייה באימפורטים עם fastapi</title>
        <dc:creator><![CDATA[koby]]></dc:creator>
        <description><![CDATA[
            <p></p><div class="lightbox-wrapper"><a class="lightbox" href="https://forums.pythonic.guru/uploads/default/original/2X/6/6890b5a121693996b53d7b287f24ba9b7f358fce.png" data-download-href="https://forums.pythonic.guru/uploads/default/6890b5a121693996b53d7b287f24ba9b7f358fce" title="image"><img src="https://forums.pythonic.guru/uploads/default/optimized/2X/6/6890b5a121693996b53d7b287f24ba9b7f358fce_2_690x281.png" alt="image" data-base62-sha1="eV1H7NWb99LdDrDPNstWM8iBTwW" width="690" height="281" srcset="https://forums.pythonic.guru/uploads/default/optimized/2X/6/6890b5a121693996b53d7b287f24ba9b7f358fce_2_690x281.png, https://forums.pythonic.guru/uploads/default/optimized/2X/6/6890b5a121693996b53d7b287f24ba9b7f358fce_2_1035x421.png 1.5x, https://forums.pythonic.guru/uploads/default/optimized/2X/6/6890b5a121693996b53d7b287f24ba9b7f358fce_2_1380x562.png 2x" data-small-upload="https://forums.pythonic.guru/uploads/default/optimized/2X/6/6890b5a121693996b53d7b287f24ba9b7f358fce_2_10x10.png"></a></div><br>
אני נתקל באי יכולת לייבא כלום מתיקיית database. התוכנה מורצת מתוך תיקיית app, בה, במקביל לקובץ ההרצה ישנה את תיקיית database, ובתוכה ישנו קובץ init. למרות זאת, נסיונות לייבא מתוכו כושלים. ניסיתי במספר דרכים שונות, עד כה ללא הצלחה. הבנתי שאחרים גם נתקלו בזה<p></p>
          <p><a href="https://forums.pythonic.guru/t/fastapi/8772/1">קריאת הנושא במלואו</a></p>
        ]]></description>
        <link>https://forums.pythonic.guru/t/fastapi/8772/1</link>
        <pubDate>Wed, 13 Jan 2021 14:08:40 +0000</pubDate>
        <guid isPermaLink="false">forums.pythonic.guru-post-8772-1</guid>
        <source url="https://forums.pythonic.guru/t/fastapi/8772.rss">בעייה באימפורטים עם fastapi</source>
      </item>
  </channel>
</rss>
